<?xml version="1.0" ?>
<!-- =================================================================================== -->
<!-- |    This document was autogenerated by xacro from /catkin_ws/src/scara_robot/urdf/scara.xacro | -->
<!-- |    EDITING THIS FILE BY HAND IS NOT RECOMMENDED                                 | -->
<!-- =================================================================================== -->
<robot name="scara_robot">
  <!-- Materiales -->
  <material name="orange">
    <color rgba="1.0 0.5 0.0 1"/>
  </material>
  <material name="purple">
    <color rgba="0.6 0.2 0.8 1"/>
  </material>
  <material name="gray">
    <color rgba="0.6 0.6 0.6 1"/>
  </material>
  <material name="celeste">
    <color rgba="0.53 0.81 0.98 1"/>
  </material>
  <!-- Base -->
  <link name="world">
    <visual>
      <geometry>
        <box size="1 1 0.01"/>
      </geometry>
      <origin rpy="0 0 0" xyz="0 0 0"/>
      <material name="gray"/>
    </visual>
  </link>
  <joint name="joint_base" type="fixed">
    <parent link="world"/>
    <child link="link_base"/>
    <origin rpy="0 0 0" xyz="0 0 0.1"/>
  </joint>
  <link name="link_base">
    <visual>
      <geometry>
        <cylinder length="0.2" radius="0.15"/>
      </geometry>
      <origin rpy="0 0 0" xyz="0 0 0.1"/>
      <material name="gray"/>
    </visual>
  </link>
  <joint name="joint_0" type="fixed">
    <parent link="link_base"/>
    <child link="link_0"/>
    <origin rpy="0 0 0" xyz="0 0 0.2"/>
  </joint>
  <link name="link_0">
    <visual>
      <geometry>
        <cylinder length="0.8" radius="0.04"/>
      </geometry>
      <origin rpy="0 0 0" xyz="0 0 0.4"/>
      <material name="celeste"/>
    </visual>
    <visual>
      <origin rpy="0 0 0" xyz="0 0 0.4"/>
      <geometry>
        <box size="0.02 0.0005 0.0005"/>
      </geometry>
      <material name="red"/>
    </visual>
    <visual>
      <origin rpy="0 0 1.5708" xyz="0 0 0.4"/>
      <geometry>
        <box size="0.02 0.0005 0.0005"/>
      </geometry>
      <material name="green"/>
    </visual>
    <visual>
      <origin rpy="0 -1.5708 0" xyz="0 0 0.4"/>
      <geometry>
        <box size="0.02 0.0005 0.0005"/>
      </geometry>
      <material name="blue"/>
    </visual>
  </link>
  <joint name="joint_1" type="revolute">
    <parent link="link_0"/>
    <child link="link_1"/>
    <origin rpy="0 0 0" xyz="0 0 0.8"/>
    <axis xyz="0 1 0"/>
    <!-- Rotación alrededor del eje Y -->
    <limit effort="1" lower="0" upper="2.6179938779914944" velocity="1.0"/>
    <!-- 0 a 150 grados en radianes -->
  </joint>
  <!-- Eslabón 1: Cilindro orientado a lo largo del eje X -->
  <link name="link_1">
    <visual>
      <!-- Definimos el origen de la caja para que se alinee correctamente -->
      <origin rpy="0 0 0" xyz="0.2 0 0"/>
      <geometry>
        <box size="0.4 0.04 0.04"/>
        <!-- Caja con longitud L1 y secciones transversales iguales al radio -->
      </geometry>
      <material name="orange"/>
    </visual>
    <visual>
      <origin rpy="0 0 0" xyz="0.2 0 0"/>
      <geometry>
        <box size="0.02 0.0005 0.0005"/>
      </geometry>
      <material name="red"/>
    </visual>
    <visual>
      <origin rpy="0 0 1.5708" xyz="0.2 0 0"/>
      <geometry>
        <box size="0.02 0.0005 0.0005"/>
      </geometry>
      <material name="green"/>
    </visual>
    <visual>
      <origin rpy="0 -1.5708 0" xyz="0.2 0 0"/>
      <geometry>
        <box size="0.02 0.0005 0.0005"/>
      </geometry>
      <material name="blue"/>
    </visual>
  </link>
  <joint name="joint_2" type="fixed">
    <parent link="link_1"/>
    <child link="link_2"/>
    <origin rpy="0 0 0" xyz="0 0 0.4"/>
  </joint>
  <link name="link_2">
    <visual>
      <geometry>
        <cylinder length="0.11" radius="0.04"/>
      </geometry>
      <origin rpy="0 0 0" xyz="0 0 0.055"/>
      <material name="orange"/>
    </visual>
    <visual>
      <origin rpy="0 0 0" xyz="0 0 0.055"/>
      <geometry>
        <box size="0.02 0.0005 0.0005"/>
      </geometry>
      <material name="red"/>
    </visual>
    <visual>
      <origin rpy="0 0 1.5708" xyz="0 0 0.055"/>
      <geometry>
        <box size="0.02 0.0005 0.0005"/>
      </geometry>
      <material name="green"/>
    </visual>
    <visual>
      <origin rpy="0 -1.5708 0" xyz="0 0 0.055"/>
      <geometry>
        <box size="0.02 0.0005 0.0005"/>
      </geometry>
      <material name="blue"/>
    </visual>
  </link>
  <joint name="joint_3" type="revolute">
    <parent link="link_2"/>
    <child link="link_3"/>
    <origin rpy="0 0 0" xyz="0 0 0.11"/>
    <axis xyz="0 0 1"/>
    <limit effort="1" lower="-3.14" upper="3.14" velocity="1.0"/>
  </joint>
  <link name="link_3">
    <visual>
      <geometry>
        <cylinder length="0.5" radius="0.04"/>
      </geometry>
      <origin rpy="0 1.5708 0" xyz="0.25 0 0"/>
      <material name="purple"/>
    </visual>
    <visual>
      <origin rpy="0 0 0" xyz="0.25 0 0"/>
      <geometry>
        <box size="0.02 0.0005 0.0005"/>
      </geometry>
      <material name="red"/>
    </visual>
    <visual>
      <origin rpy="0 0 1.5708" xyz="0.25 0 0"/>
      <geometry>
        <box size="0.02 0.0005 0.0005"/>
      </geometry>
      <material name="green"/>
    </visual>
    <visual>
      <origin rpy="0 -1.5708 0" xyz="0.25 0 0"/>
      <geometry>
        <box size="0.02 0.0005 0.0005"/>
      </geometry>
      <material name="blue"/>
    </visual>
  </link>
  <joint name="joint_4" type="fixed">
    <parent link="link_3"/>
    <child link="link_4"/>
    <origin rpy="0 0 0" xyz="0.5 0 0"/>
  </joint>
  <link name="link_4">
    <visual>
      <geometry>
        <cylinder length="0.45" radius="0.04"/>
      </geometry>
      <origin rpy="0 0 0" xyz="0 0 -0.225"/>
      <material name="purple"/>
    </visual>
    <visual>
      <origin rpy="0 0 0" xyz="0 0 -0.225"/>
      <geometry>
        <box size="0.02 0.0005 0.0005"/>
      </geometry>
      <material name="red"/>
    </visual>
    <visual>
      <origin rpy="0 0 1.5708" xyz="0 0 -0.225"/>
      <geometry>
        <box size="0.02 0.0005 0.0005"/>
      </geometry>
      <material name="green"/>
    </visual>
    <visual>
      <origin rpy="0 -1.5708 0" xyz="0 0 -0.225"/>
      <geometry>
        <box size="0.02 0.0005 0.0005"/>
      </geometry>
      <material name="blue"/>
    </visual>
  </link>
  <joint name="joint_5" type="prismatic">
    <parent link="link_4"/>
    <child link="link_5"/>
    <origin rpy="0 0 0" xyz="0 0 -0.45"/>
    <axis xyz="0 0 -1"/>
    <limit effort="1" lower="0.0" upper="0.4" velocity="0.5"/>
  </joint>
  <link name="link_5">
    <visual>
      <geometry>
        <cylinder length="0.2" radius="0.04"/>
      </geometry>
      <origin rpy="0 0 0" xyz="0 0 -0.1"/>
      <material name="gray"/>
    </visual>
    <visual>
      <origin rpy="0 0 0" xyz="0 0 -0.1"/>
      <geometry>
        <box size="0.02 0.0005 0.0005"/>
      </geometry>
      <material name="red"/>
    </visual>
    <visual>
      <origin rpy="0 0 1.5708" xyz="0 0 -0.1"/>
      <geometry>
        <box size="0.02 0.0005 0.0005"/>
      </geometry>
      <material name="green"/>
    </visual>
    <visual>
      <origin rpy="0 -1.5708 0" xyz="0 0 -0.1"/>
      <geometry>
        <box size="0.02 0.0005 0.0005"/>
      </geometry>
      <material name="blue"/>
    </visual>
  </link>
  <joint name="joint_6" type="revolute">
    <parent link="link_5"/>
    <child link="link_6"/>
    <origin rpy="0 0 0" xyz="0 0 -0.2"/>
    <axis xyz="0 0 1"/>
    <limit effort="1" lower="-3.14" upper="3.14" velocity="1.0"/>
  </joint>
  <link name="link_6">
    <visual>
      <geometry>
        <cylinder length="0.6" radius="0.04"/>
      </geometry>
      <origin rpy="0 0 0" xyz="0 0 -0.3"/>
      <material name="gray"/>
    </visual>
    <visual>
      <origin rpy="0 0 0" xyz="0 0 -0.3"/>
      <geometry>
        <box size="0.02 0.0005 0.0005"/>
      </geometry>
      <material name="red"/>
    </visual>
    <visual>
      <origin rpy="0 0 1.5708" xyz="0 0 -0.3"/>
      <geometry>
        <box size="0.02 0.0005 0.0005"/>
      </geometry>
      <material name="green"/>
    </visual>
    <visual>
      <origin rpy="0 -1.5708 0" xyz="0 0 -0.3"/>
      <geometry>
        <box size="0.02 0.0005 0.0005"/>
      </geometry>
      <material name="blue"/>
    </visual>
  </link>
  <joint name="joint_tcp" type="fixed">
    <parent link="link_6"/>
    <child link="tcp"/>
    <origin rpy="0 0 0" xyz="0 0 -0.6"/>
  </joint>
  <link name="tcp">
    <visual>
      <geometry>
        <sphere radius="0.04"/>
      </geometry>
      <material name="gray"/>
    </visual>
    <visual>
      <origin rpy="0 0 0" xyz="0 0 0"/>
      <geometry>
        <box size="0.02 0.0005 0.0005"/>
      </geometry>
      <material name="red"/>
    </visual>
    <visual>
      <origin rpy="0 0 1.5708" xyz="0 0 0"/>
      <geometry>
        <box size="0.02 0.0005 0.0005"/>
      </geometry>
      <material name="green"/>
    </visual>
    <visual>
      <origin rpy="0 -1.5708 0" xyz="0 0 0"/>
      <geometry>
        <box size="0.02 0.0005 0.0005"/>
      </geometry>
      <material name="blue"/>
    </visual>
  </link>
</robot>

