<?xml version="1.0" ?>
<!-- =================================================================================== -->
<!-- |    This document was autogenerated by xacro from /catkin_ws/src/scara_robot/urdf/scara.xacro | -->
<!-- |    EDITING THIS FILE BY HAND IS NOT RECOMMENDED                                 | -->
<!-- =================================================================================== -->
<robot name="scara_robot">
    <!-- Materiales -->
    <material name="orange">
        <color rgba="1.0 0.5 0.0 1" />
    </material>
    <material name="purple">
        <color rgba="0.6 0.2 0.8 1" />
    </material>
    <material name="yellow">
        <color rgba="1.0 1.0 0.0 1" />
    </material>
    <material name="gray">
        <color rgba="0.6 0.6 0.6 1" />
    </material>
    <material name="red">
        <color rgba="1 0 0 1" />
    </material>
    <material name="green">
        <color rgba="0 1 0 1" />
    </material>
    <material name="blue">
        <color rgba="0 0 1 1" />
    </material>
    <material name="celeste">
        <color rgba="0.53 0.81 0.98 1" />
    </material>
    <!-- Link base mundial -->
    <link name="world">
        <visual>
            <geometry>
                <box size="2.5 2.5 0.01" />
            </geometry>
            <origin rpy="0 0 0" xyz="0 0 0" />
            <material name="gray" />
        </visual>
        <collision>
            <geometry>
                <box size="2.5 2.5 0.01" />
            </geometry>
            <origin rpy="0 0 0" xyz="0 0 0" />
            <material name="gray" />
        </collision>
        <inertial>
            <mass value="0.1" />
            <origin xyz="0 0 0" rpy="0 0 0" />
            <inertia ixx="0.03" iyy="0.03" izz="0.03" ixy="0.0" ixz="0.0" iyz="0.0" />
        </inertial>
    </link>
    <!-- Joint desde el mundo al pedestal -->
    <joint name="world_to_pedestal" type="fixed">
        <parent link="world" />
        <child link="pedestal" />
        <origin rpy="0 0 0" xyz="0 0 0" />
    </joint>
    <!-- Pedestal fijo -->
    <link name="pedestal">
        <visual>
            <geometry>
                <cylinder length="0.2" radius="0.15" />
            </geometry>
            <origin rpy="0 0 0" xyz="0 0 0.1" />
            <material name="gray" />
        </visual>
        <collision>
            <geometry>
                <cylinder length="0.2" radius="0.15" />
            </geometry>
            <origin rpy="0 0 0" xyz="0 0 0.1" />
            <material name="gray" />
        </collision>
        <inertial>
            <mass value="0.1" />
            <origin xyz="0 0 0" rpy="0 0 0" />
            <inertia ixx="0.03" iyy="0.03" izz="0.03" ixy="0.0" ixz="0.0" iyz="0.0" />
        </inertial>
    </link>
    <!-- Columna vertical giratoria (celeste) -->
    <link name="base_link">
        <visual>
            <geometry>
                <cylinder length="0.8" radius="0.1" />
            </geometry>
            <origin rpy="0 0 0" xyz="0 0 0.35" />
            <material name="celeste" />
        </visual>
        <visual>
            <origin rpy="0 0 0" xyz="0 0 0.4" />
            <geometry>
                <box size="0.02 0.0005 0.0005" />
            </geometry>
            <material name="red" />
        </visual>
        <visual>
            <origin rpy="0 0 1.5708" xyz="0 0 0.4" />
            <geometry>
                <box size="0.02 0.0005 0.0005" />
            </geometry>
            <material name="green" />
        </visual>
        <visual>
            <origin rpy="0 -1.5708 0" xyz="0 0 0.4" />
            <geometry>
                <box size="0.02 0.0005 0.0005" />
            </geometry>
            <material name="blue" />
        </visual>
        <collision>
            <geometry>
                <cylinder length="0.8" radius="0.1" />
            </geometry>
            <origin rpy="0 0 0" xyz="0 0 0.35" />
            <material name="celeste" />
        </collision>
        <inertial>
            <mass value="0.1" />
            <origin xyz="0 0 0" rpy="0 0 0" />
            <inertia ixx="0.03" iyy="0.03" izz="0.03" ixy="0.0" ixz="0.0" iyz="0.0" />
        </inertial>
    </link>
    <joint name="joint_0" type="revolute">
        <parent link="pedestal" />
        <child link="base_link" />
        <origin rpy="0 0 0" xyz="0 0 0.2" />
        <axis xyz="0 0 1" />
        <!-- ← Eje de rotación deseado: Y -->
        <limit effort="1" lower="-2.61799" upper="2.61799" velocity="1.0" />
    </joint>
    <!-- Primer brazo horizontal naranja -->
    <link name="link_1">
        <visual>
            <geometry>
                <cylinder length="0.4" radius="0.04" />
            </geometry>
            <origin rpy="0 1.5708 0" xyz="0.2 0 0" />
            <!--  Cilindro apuntando en Z -->
            <material name="orange" />
        </visual>
        <visual>
            <origin rpy="0 0 0" xyz="0 0 0.2" />
            <geometry>
                <box size="0.02 0.0005 0.0005" />
            </geometry>
            <material name="red" />
        </visual>
        <visual>
            <origin rpy="0 0 1.5708" xyz="0 0 0.2" />
            <geometry>
                <box size="0.02 0.0005 0.0005" />
            </geometry>
            <material name="green" />
        </visual>
        <visual>
            <origin rpy="0 -1.5708 0" xyz="0 0 0.2" />
            <geometry>
                <box size="0.02 0.0005 0.0005" />
            </geometry>
            <material name="blue" />
        </visual>
        <collision>
            <geometry>
                <cylinder length="0.4" radius="0.04" />
            </geometry>
            <origin rpy="0 1.5708 0" xyz="0.2 0 0" />
            <material name="orange" />
        </collision>
        <inertial>
            <mass value="0.1" />
            <origin xyz="0 0 0" rpy="0 0 0" />
            <inertia ixx="0.03" iyy="0.03" izz="0.03" ixy="0.0" ixz="0.0" iyz="0.0" />
        </inertial>
    </link>
    <joint name="joint_1" type="revolute">
        <parent link="base_link" />
        <child link="link_1" />
        <origin rpy="0 0 0" xyz="0 0 0.8" />
        <axis xyz="0 1 0" />
        <!-- ← Eje de rotación deseado: Y -->
        <limit effort="1" lower="-1.5708" upper="0" velocity="1.0" />
    </joint>
    <!-- Parte vertical de la L naranja (Z1 arriba) -->
    <link name="link_1_vertical">
        <visual>
            <geometry>
                <cylinder length="0.11" radius="0.04" />
            </geometry>
            <origin rpy="0 0 0" xyz="0 0 0.055" />
            <material name="orange" />
        </visual>
        <visual>
            <origin rpy="0 0 0" xyz="0 0 0.055" />
            <geometry>
                <box size="0.02 0.0005 0.0005" />
            </geometry>
            <material name="red" />
        </visual>
        <visual>
            <origin rpy="0 0 1.5708" xyz="0 0 0.055" />
            <geometry>
                <box size="0.02 0.0005 0.0005" />
            </geometry>
            <material name="green" />
        </visual>
        <visual>
            <origin rpy="0 -1.5708 0" xyz="0 0 0.055" />
            <geometry>
                <box size="0.02 0.0005 0.0005" />
            </geometry>
            <material name="blue" />
        </visual>
        <collision>
            <geometry>
                <cylinder length="0.11" radius="0.04" />
            </geometry>
            <origin rpy="0 0 0" xyz="0 0 0.055" />
            <material name="orange" />
        </collision>
        <inertial>
            <mass value="0.1" />
            <origin xyz="0 0 0" rpy="0 0 0" />
            <inertia ixx="0.03" iyy="0.03" izz="0.03" ixy="0.0" ixz="0.0" iyz="0.0" />
        </inertial>
    </link>
    <joint name="joint_2" type="fixed">
        <parent link="link_1" />
        <child link="link_1_vertical" />
        <origin rpy="0 0 0" xyz="0.4 0 0" />
    </joint>
    <!-- Parte horizontal de la L morada -->
    <link name="link_2">
        <visual>
            <geometry>
                <cylinder length="0.5" radius="0.04" />
            </geometry>
            <origin rpy="0 1.5708 0" xyz="0.25 0 0" />
            <material name="purple" />
        </visual>
        <visual>
            <origin rpy="0 0 0" xyz="0.25 0 0" />
            <geometry>
                <box size="0.02 0.0005 0.0005" />
            </geometry>
            <material name="red" />
        </visual>
        <visual>
            <origin rpy="0 0 1.5708" xyz="0.25 0 0" />
            <geometry>
                <box size="0.02 0.0005 0.0005" />
            </geometry>
            <material name="green" />
        </visual>
        <visual>
            <origin rpy="0 -1.5708 0" xyz="0.25 0 0" />
            <geometry>
                <box size="0.02 0.0005 0.0005" />
            </geometry>
            <material name="blue" />
        </visual>
        <collision>
            <geometry>
                <cylinder length="0.5" radius="0.04" />
            </geometry>
            <origin rpy="0 1.5708 0" xyz="0.25 0 0" />
            <material name="purple" />
        </collision>
        <inertial>
            <mass value="0.1" />
            <origin xyz="0 0 0" rpy="0 0 0" />
            <inertia ixx="0.03" iyy="0.03" izz="0.03" ixy="0.0" ixz="0.0" iyz="0.0" />
        </inertial>
    </link>
    <joint name="joint_3" type="revolute">
        <parent link="link_1_vertical" />
        <child link="link_2" />
        <origin rpy="0 0 0" xyz="0 0 0.11" />
        <axis xyz="0 0 1" />
        <limit effort="1" lower="-2.96706" upper="2.96706" velocity="1.0" />
    </joint>
    <!-- Parte vertical de la L morada -->
    <link name="link_2_down">
        <visual>
            <geometry>
                <cylinder length="0.45" radius="0.04" />
            </geometry>
            <origin rpy="0 0 0" xyz="0 0 -0.225" />
            <material name="purple" />
        </visual>
        <visual>
            <origin rpy="0 0 0" xyz="0 0 -0.225" />
            <geometry>
                <box size="0.02 0.0005 0.0005" />
            </geometry>
            <material name="red" />
        </visual>
        <visual>
            <origin rpy="0 0 1.5708" xyz="0 0 -0.225" />
            <geometry>
                <box size="0.02 0.0005 0.0005" />
            </geometry>
            <material name="green" />
        </visual>
        <visual>
            <origin rpy="0 -1.5708 0" xyz="0 0 -0.225" />
            <geometry>
                <box size="0.02 0.0005 0.0005" />
            </geometry>
            <material name="blue" />
        </visual>
        <collision>
            <geometry>
                <cylinder length="0.45" radius="0.04" />
            </geometry>
            <origin rpy="0 0 0" xyz="0 0 -0.225" />
            <material name="purple" />
        </collision>
        <inertial>
            <mass value="0.1" />
            <origin xyz="0 0 0" rpy="0 0 0" />
            <inertia ixx="0.03" iyy="0.03" izz="0.03" ixy="0.0" ixz="0.0" iyz="0.0" />
        </inertial>
    </link>
    <joint name="joint_4" type="fixed">
        <parent link="link_2" />
        <child link="link_2_down" />
        <origin rpy="0 0 0" xyz="0.5 0 0" />
    </joint>
    <!-- Eje prismático con parte fija de 0.2 m -->
    <link name="link_3">
        <visual>
            <geometry>
                <cylinder length="0.2" radius="0.04" />
            </geometry>
            <origin rpy="0 0 0" xyz="0 0 -0.1" />
            <material name="gray" />
        </visual>
        <visual>
            <origin rpy="0 0 0" xyz="0 0 -0.1" />
            <geometry>
                <box size="0.02 0.0005 0.0005" />
            </geometry>
            <material name="red" />
        </visual>
        <visual>
            <origin rpy="0 0 1.5708" xyz="0 0 -0.1" />
            <geometry>
                <box size="0.02 0.0005 0.0005" />
            </geometry>
            <material name="green" />
        </visual>
        <visual>
            <origin rpy="0 -1.5708 0" xyz="0 0 -0.1" />
            <geometry>
                <box size="0.02 0.0005 0.0005" />
            </geometry>
            <material name="blue" />
        </visual>
        <collision>
            <geometry>
                <cylinder length="0.2" radius="0.04" />
            </geometry>
            <origin rpy="0 0 0" xyz="0 0 -0.1" />
            <material name="gray" />
        </collision>
        <inertial>
            <mass value="0.1" />
            <origin xyz="0 0 0" rpy="0 0 0" />
            <inertia ixx="0.03" iyy="0.03" izz="0.03" ixy="0.0" ixz="0.0" iyz="0.0" />
        </inertial>
    </link>
    <joint name="joint_5" type="prismatic">
        <parent link="link_2_down" />
        <child link="link_3" />
        <origin rpy="0 0 0" xyz="0 0 -0.45" />
        <axis xyz="0 0 -1" />
        <limit effort="1" lower="0.0" upper="0.2" velocity="0.5" />
    </joint>
    <link name="link_4">
        <visual>
            <geometry>
                <cylinder length="0.2" radius="0.07" />
            </geometry>
            <origin rpy="0 0 0" xyz="0 0 -0.1" />
            <material name="gray" />
        </visual>
        <visual>
            <origin rpy="0 0 0" xyz="0 0 -0.1" />
            <geometry>
                <box size="0.02 0.0005 0.0005" />
            </geometry>
            <material name="red" />
        </visual>
        <visual>
            <origin rpy="0 0 1.5708" xyz="0 0 -0.1" />
            <geometry>
                <box size="0.02 0.0005 0.0005" />
            </geometry>
            <material name="green" />
        </visual>
        <visual>
            <origin rpy="0 -1.5708 0" xyz="0 0 -0.1" />
            <geometry>
                <box size="0.02 0.0005 0.0005" />
            </geometry>
            <material name="blue" />
        </visual>
        <collision>
            <geometry>
                <cylinder length="0.2" radius="0.07" />
            </geometry>
            <origin rpy="0 0 0" xyz="0 0 -0.1" />
            <material name="gray" />
        </collision>
        <inertial>
            <mass value="0.1" />
            <origin xyz="0 0 0" rpy="0 0 0" />
            <inertia ixx="0.03" iyy="0.03" izz="0.03" ixy="0.0" ixz="0.0" iyz="0.0" />
        </inertial>
    </link>
    <joint name="joint_6" type="revolute">
        <parent link="link_3" />
        <child link="link_4" />
        <origin rpy="0 0 0" xyz="0 0 -0.2" />
        <axis xyz="0 0 1" />
        <limit effort="1" lower="-3.14" upper="3.14" velocity="1.0" />
    </joint>
    <link name="tcp">
        <visual>
            <geometry>
                <sphere radius="0.04" />
            </geometry>
            <material name="gray" />
        </visual>
        <visual>
            <origin rpy="0 0 0" xyz="0 0 0" />
            <geometry>
                <box size="0.02 0.0005 0.0005" />
            </geometry>
            <material name="red" />
        </visual>
        <visual>
            <origin rpy="0 0 1.5708" xyz="0 0 0" />
            <geometry>
                <box size="0.02 0.0005 0.0005" />
            </geometry>
            <material name="green" />
        </visual>
        <visual>
            <origin rpy="0 -1.5708 0" xyz="0 0 0" />
            <geometry>
                <box size="0.02 0.0005 0.0005" />
            </geometry>
            <material name="blue" />
        </visual>
        <collision>
            <geometry>
                <sphere radius="0.04" />
            </geometry>
            <material name="gray" />
        </collision>
        <inertial>
            <mass value="0.1" />
            <origin xyz="0 0 0" rpy="0 0 0" />
            <inertia ixx="0.03" iyy="0.03" izz="0.03" ixy="0.0" ixz="0.0" iyz="0.0" />
        </inertial>
    </link>
    <joint name="joint_tcp" type="fixed">
        <parent link="link_4" />
        <child link="tcp" />
        <origin rpy="0 0 0" xyz="0 0 -0.2" />
    </joint>
    <transmission name="trans_joint_0">
        <type>transmission_interface/SimpleTransmission</type>
        <joint name="joint_0">
            <hardwareInterface>hardware_interface/EffortJointInterface</hardwareInterface>
        </joint>
        <actuator name="joint_0_motor">
            <hardwareInterface>hardware_interface/EffortJointInterface</hardwareInterface>
            <mechanicalReduction>1</mechanicalReduction>
        </actuator>
    </transmission>
    <transmission name="trans_joint_1">
        <type>transmission_interface/SimpleTransmission</type>
        <joint name="joint_1">
            <hardwareInterface>hardware_interface/EffortJointInterface</hardwareInterface>
        </joint>
        <actuator name="joint_1_motor">
            <hardwareInterface>hardware_interface/EffortJointInterface</hardwareInterface>
            <mechanicalReduction>1</mechanicalReduction>
        </actuator>
    </transmission>
    <transmission name="trans_joint_3">
        <type>transmission_interface/SimpleTransmission</type>
        <joint name="joint_3">
            <hardwareInterface>hardware_interface/EffortJointInterface</hardwareInterface>
        </joint>
        <actuator name="joint_3_motor">
            <hardwareInterface>hardware_interface/EffortJointInterface</hardwareInterface>
            <mechanicalReduction>1</mechanicalReduction>
        </actuator>
    </transmission>
    <transmission name="trans_joint_5">
        <type>transmission_interface/SimpleTransmission</type>
        <joint name="joint_5">
            <hardwareInterface>hardware_interface/EffortJointInterface</hardwareInterface>
        </joint>
        <actuator name="joint_5_motor">
            <hardwareInterface>hardware_interface/EffortJointInterface</hardwareInterface>
            <mechanicalReduction>1</mechanicalReduction>
        </actuator>
    </transmission>
    <transmission name="trans_joint_6">
        <type>transmission_interface/SimpleTransmission</type>
        <joint name="joint_6">
            <hardwareInterface>hardware_interface/EffortJointInterface</hardwareInterface>
        </joint>
        <actuator name="joint_6_motor">
            <hardwareInterface>hardware_interface/EffortJointInterface</hardwareInterface>
            <mechanicalReduction>1</mechanicalReduction>
        </actuator>
    </transmission>
    <gazebo>
        <plugin name="gazebo_ros_control" filename="libgazebo_ros_control.so">
            <robotNamespace>/</robotNamespace>
        </plugin>
    </gazebo>
</robot>

